[2024-05-30T15:19:58.237+0000] {local_task_job_runner.py:120} INFO - ::group::Pre task execution logs
[2024-05-30T15:19:58.272+0000] {taskinstance.py:2073} INFO - Dependencies all met for dep_context=non-requeueable deps ti=<TaskInstance: fetch_imdb_data.fetch_data_from_imdb manual__2024-05-30T15:19:28.319748+00:00 [queued]>
[2024-05-30T15:19:58.283+0000] {taskinstance.py:2073} INFO - Dependencies all met for dep_context=requeueable deps ti=<TaskInstance: fetch_imdb_data.fetch_data_from_imdb manual__2024-05-30T15:19:28.319748+00:00 [queued]>
[2024-05-30T15:19:58.283+0000] {taskinstance.py:2303} INFO - Starting attempt 2 of 2
[2024-05-30T15:19:58.293+0000] {taskinstance.py:2327} INFO - Executing <Task(PythonOperator): fetch_data_from_imdb> on 2024-05-30 15:19:28.319748+00:00
[2024-05-30T15:19:58.322+0000] {standard_task_runner.py:90} INFO - Running: ['***', 'tasks', 'run', 'fetch_imdb_data', 'fetch_data_from_imdb', 'manual__2024-05-30T15:19:28.319748+00:00', '--job-id', '105', '--raw', '--subdir', 'DAGS_FOLDER/test.py', '--cfg-path', '/tmp/tmpf30s0r20']
[2024-05-30T15:19:58.331+0000] {standard_task_runner.py:91} INFO - Job 105: Subtask fetch_data_from_imdb
[2024-05-30T15:19:58.330+0000] {logging_mixin.py:188} WARNING - /home/***/.local/lib/python3.12/site-packages/***/task/task_runner/standard_task_runner.py:61 DeprecationWarning: This process (pid=784) is multi-threaded, use of fork() may lead to deadlocks in the child.
[2024-05-30T15:19:58.339+0000] {standard_task_runner.py:63} INFO - Started process 791 to run task
[2024-05-30T15:19:58.429+0000] {task_command.py:426} INFO - Running <TaskInstance: fetch_imdb_data.fetch_data_from_imdb manual__2024-05-30T15:19:28.319748+00:00 [running]> on host e24e7042a181
[2024-05-30T15:19:58.558+0000] {taskinstance.py:2644} INFO - Exporting env vars: AIRFLOW_CTX_DAG_EMAIL='***@example.com' AIRFLOW_CTX_DAG_OWNER='***' AIRFLOW_CTX_DAG_ID='fetch_imdb_data' AIRFLOW_CTX_TASK_ID='fetch_data_from_imdb' AIRFLOW_CTX_EXECUTION_DATE='2024-05-30T15:19:28.319748+00:00' AIRFLOW_CTX_TRY_NUMBER='2' AIRFLOW_CTX_DAG_RUN_ID='manual__2024-05-30T15:19:28.319748+00:00'
[2024-05-30T15:19:58.562+0000] {taskinstance.py:430} INFO - ::endgroup::
[2024-05-30T15:19:58.564+0000] {logging_mixin.py:188} INFO - Fetching data from IMDb...
[2024-05-30T15:19:58.564+0000] {logging_mixin.py:188} INFO - Target path: /Users/ilan/***-docker/datalake/raw/imdb/MovieRating/20240530/
[2024-05-30T15:19:58.565+0000] {taskinstance.py:441} INFO - ::group::Post task execution logs
[2024-05-30T15:19:58.565+0000] {taskinstance.py:2890} ERROR - Task failed with exception
Traceback (most recent call last):
  File "/home/airflow/.local/lib/python3.12/site-packages/airflow/models/taskinstance.py", line 465, in _execute_task
    result = _execute_callable(context=context, **execute_callable_kwargs)
             ^^^^^^^^^^^^^^^^^^^^^^^^^^^^^^^^^^^^^^^^^^^^^^^^^^^^^^^^^^^^^
  File "/home/airflow/.local/lib/python3.12/site-packages/airflow/models/taskinstance.py", line 432, in _execute_callable
    return execute_callable(context=context, **execute_callable_kwargs)
           ^^^^^^^^^^^^^^^^^^^^^^^^^^^^^^^^^^^^^^^^^^^^^^^^^^^^^^^^^^^^
  File "/home/airflow/.local/lib/python3.12/site-packages/airflow/models/baseoperator.py", line 400, in wrapper
    return func(self, *args, **kwargs)
           ^^^^^^^^^^^^^^^^^^^^^^^^^^^
  File "/home/airflow/.local/lib/python3.12/site-packages/airflow/operators/python.py", line 235, in execute
    return_value = self.execute_callable()
                   ^^^^^^^^^^^^^^^^^^^^^^^
  File "/home/airflow/.local/lib/python3.12/site-packages/airflow/operators/python.py", line 252, in execute_callable
    return self.python_callable(*self.op_args, **self.op_kwargs)
           ^^^^^^^^^^^^^^^^^^^^^^^^^^^^^^^^^^^^^^^^^^^^^^^^^^^^^
  File "/opt/airflow/dags/test.py", line 19, in fetch_data_from_imdb
    os.makedirs(TARGET_PATH)
  File "<frozen os>", line 215, in makedirs
  File "<frozen os>", line 215, in makedirs
  File "<frozen os>", line 215, in makedirs
  [Previous line repeated 4 more times]
  File "<frozen os>", line 225, in makedirs
PermissionError: [Errno 13] Permission denied: '/Users'
[2024-05-30T15:19:58.585+0000] {taskinstance.py:1205} INFO - Marking task as FAILED. dag_id=fetch_imdb_data, task_id=fetch_data_from_imdb, execution_date=20240530T151928, start_date=20240530T151958, end_date=20240530T151958
[2024-05-30T15:19:58.612+0000] {standard_task_runner.py:110} ERROR - Failed to execute job 105 for task fetch_data_from_imdb ([Errno 13] Permission denied: '/Users'; 791)
[2024-05-30T15:19:58.660+0000] {local_task_job_runner.py:240} INFO - Task exited with return code 1
[2024-05-30T15:19:58.694+0000] {taskinstance.py:3482} INFO - 0 downstream tasks scheduled from follow-on schedule check
[2024-05-30T15:19:58.704+0000] {local_task_job_runner.py:222} INFO - ::endgroup::
